2019-11-14 18:45:29,186 : ERROR : Exception on /results_list [GET] [in /home/jevisan/ourPersonalities/venv/lib/python3.6/site-packages/flask/app.py:1891]
Traceback (most recent call last):
  File "/home/jevisan/ourPersonalities/venv/lib/python3.6/site-packages/flask/app.py", line 2446, in wsgi_app
    response = self.full_dispatch_request()
  File "/home/jevisan/ourPersonalities/venv/lib/python3.6/site-packages/flask/app.py", line 1951, in full_dispatch_request
    rv = self.handle_user_exception(e)
  File "/home/jevisan/ourPersonalities/venv/lib/python3.6/site-packages/flask/app.py", line 1820, in handle_user_exception
    reraise(exc_type, exc_value, tb)
  File "/home/jevisan/ourPersonalities/venv/lib/python3.6/site-packages/flask/_compat.py", line 39, in reraise
    raise value
  File "/home/jevisan/ourPersonalities/venv/lib/python3.6/site-packages/flask/app.py", line 1949, in full_dispatch_request
    rv = self.dispatch_request()
  File "/home/jevisan/ourPersonalities/venv/lib/python3.6/site-packages/flask/app.py", line 1935, in dispatch_request
    return self.view_functions[rule.endpoint](**req.view_args)
  File "/home/jevisan/ourPersonalities/venv/lib/python3.6/site-packages/flask_login/utils.py", line 261, in decorated_view
    return func(*args, **kwargs)
  File "/home/jevisan/ourPersonalities/app/main/routes.py", line 133, in results_list
    print("lista de resultados:", results_dict)
NameError: name 'results_dict' is not defined
2019-11-14 18:45:58,081 : INFO : ourPersonalities startup [in /home/jevisan/ourPersonalities/app/__init__.py:74]
2019-11-14 18:50:51,072 : INFO : ourPersonalities startup [in /home/jevisan/ourPersonalities/app/__init__.py:74]
2019-11-14 18:50:55,527 : ERROR : Exception on /results_list [GET] [in /home/jevisan/ourPersonalities/venv/lib/python3.6/site-packages/flask/app.py:1891]
Traceback (most recent call last):
  File "/home/jevisan/ourPersonalities/venv/lib/python3.6/site-packages/flask/app.py", line 2446, in wsgi_app
    response = self.full_dispatch_request()
  File "/home/jevisan/ourPersonalities/venv/lib/python3.6/site-packages/flask/app.py", line 1951, in full_dispatch_request
    rv = self.handle_user_exception(e)
  File "/home/jevisan/ourPersonalities/venv/lib/python3.6/site-packages/flask/app.py", line 1820, in handle_user_exception
    reraise(exc_type, exc_value, tb)
  File "/home/jevisan/ourPersonalities/venv/lib/python3.6/site-packages/flask/_compat.py", line 39, in reraise
    raise value
  File "/home/jevisan/ourPersonalities/venv/lib/python3.6/site-packages/flask/app.py", line 1949, in full_dispatch_request
    rv = self.dispatch_request()
  File "/home/jevisan/ourPersonalities/venv/lib/python3.6/site-packages/flask/app.py", line 1935, in dispatch_request
    return self.view_functions[rule.endpoint](**req.view_args)
  File "/home/jevisan/ourPersonalities/venv/lib/python3.6/site-packages/flask_login/utils.py", line 261, in decorated_view
    return func(*args, **kwargs)
  File "/home/jevisan/ourPersonalities/app/main/routes.py", line 135, in results_list
    return render_template('results_list.html', title='Lista de análisis', data=data)
  File "/home/jevisan/ourPersonalities/venv/lib/python3.6/site-packages/flask/templating.py", line 140, in render_template
    ctx.app,
  File "/home/jevisan/ourPersonalities/venv/lib/python3.6/site-packages/flask/templating.py", line 120, in _render
    rv = template.render(context)
  File "/home/jevisan/ourPersonalities/venv/lib/python3.6/site-packages/jinja2/asyncsupport.py", line 76, in render
    return original_render(self, *args, **kwargs)
  File "/home/jevisan/ourPersonalities/venv/lib/python3.6/site-packages/jinja2/environment.py", line 1008, in render
    return self.environment.handle_exception(exc_info, True)
  File "/home/jevisan/ourPersonalities/venv/lib/python3.6/site-packages/jinja2/environment.py", line 780, in handle_exception
    reraise(exc_type, exc_value, tb)
  File "/home/jevisan/ourPersonalities/venv/lib/python3.6/site-packages/jinja2/_compat.py", line 37, in reraise
    raise value.with_traceback(tb)
  File "/home/jevisan/ourPersonalities/app/templates/results_list.html", line 1, in top-level template code
    {% extends "base.html" %}
  File "/home/jevisan/ourPersonalities/app/templates/base.html", line 1, in top-level template code
    {% extends 'bootstrap/base.html' %}
  File "/home/jevisan/ourPersonalities/venv/lib/python3.6/site-packages/flask_bootstrap/templates/bootstrap/base.html", line 1, in top-level template code
    {% block doc -%}
  File "/home/jevisan/ourPersonalities/venv/lib/python3.6/site-packages/flask_bootstrap/templates/bootstrap/base.html", line 4, in block "doc"
    {%- block html %}
  File "/home/jevisan/ourPersonalities/venv/lib/python3.6/site-packages/flask_bootstrap/templates/bootstrap/base.html", line 20, in block "html"
    {% block body -%}
  File "/home/jevisan/ourPersonalities/venv/lib/python3.6/site-packages/flask_bootstrap/templates/bootstrap/base.html", line 23, in block "body"
    {% block content -%}
  File "/home/jevisan/ourPersonalities/app/templates/base.html", line 42, in block "content"
    {% block app_content %}{% endblock %}
  File "/home/jevisan/ourPersonalities/app/templates/results_list.html", line 15, in block "app_content"
    {% for key, value in data.items() %}
jinja2.exceptions.UndefinedError: 'None' has no attribute 'items'
2019-11-14 18:51:25,589 : INFO : ourPersonalities startup [in /home/jevisan/ourPersonalities/app/__init__.py:74]
2019-11-14 18:51:34,827 : ERROR : Exception on /results_list [GET] [in /home/jevisan/ourPersonalities/venv/lib/python3.6/site-packages/flask/app.py:1891]
Traceback (most recent call last):
  File "/home/jevisan/ourPersonalities/venv/lib/python3.6/site-packages/flask/app.py", line 2446, in wsgi_app
    response = self.full_dispatch_request()
  File "/home/jevisan/ourPersonalities/venv/lib/python3.6/site-packages/flask/app.py", line 1951, in full_dispatch_request
    rv = self.handle_user_exception(e)
  File "/home/jevisan/ourPersonalities/venv/lib/python3.6/site-packages/flask/app.py", line 1820, in handle_user_exception
    reraise(exc_type, exc_value, tb)
  File "/home/jevisan/ourPersonalities/venv/lib/python3.6/site-packages/flask/_compat.py", line 39, in reraise
    raise value
  File "/home/jevisan/ourPersonalities/venv/lib/python3.6/site-packages/flask/app.py", line 1949, in full_dispatch_request
    rv = self.dispatch_request()
  File "/home/jevisan/ourPersonalities/venv/lib/python3.6/site-packages/flask/app.py", line 1935, in dispatch_request
    return self.view_functions[rule.endpoint](**req.view_args)
  File "/home/jevisan/ourPersonalities/venv/lib/python3.6/site-packages/flask_login/utils.py", line 261, in decorated_view
    return func(*args, **kwargs)
  File "/home/jevisan/ourPersonalities/app/main/routes.py", line 135, in results_list
    return render_template('results_list.html', title='Lista de análisis', data=data)
  File "/home/jevisan/ourPersonalities/venv/lib/python3.6/site-packages/flask/templating.py", line 140, in render_template
    ctx.app,
  File "/home/jevisan/ourPersonalities/venv/lib/python3.6/site-packages/flask/templating.py", line 120, in _render
    rv = template.render(context)
  File "/home/jevisan/ourPersonalities/venv/lib/python3.6/site-packages/jinja2/asyncsupport.py", line 76, in render
    return original_render(self, *args, **kwargs)
  File "/home/jevisan/ourPersonalities/venv/lib/python3.6/site-packages/jinja2/environment.py", line 1008, in render
    return self.environment.handle_exception(exc_info, True)
  File "/home/jevisan/ourPersonalities/venv/lib/python3.6/site-packages/jinja2/environment.py", line 780, in handle_exception
    reraise(exc_type, exc_value, tb)
  File "/home/jevisan/ourPersonalities/venv/lib/python3.6/site-packages/jinja2/_compat.py", line 37, in reraise
    raise value.with_traceback(tb)
  File "/home/jevisan/ourPersonalities/app/templates/results_list.html", line 1, in top-level template code
    {% extends "base.html" %}
  File "/home/jevisan/ourPersonalities/app/templates/base.html", line 1, in top-level template code
    {% extends 'bootstrap/base.html' %}
  File "/home/jevisan/ourPersonalities/venv/lib/python3.6/site-packages/flask_bootstrap/templates/bootstrap/base.html", line 1, in top-level template code
    {% block doc -%}
  File "/home/jevisan/ourPersonalities/venv/lib/python3.6/site-packages/flask_bootstrap/templates/bootstrap/base.html", line 4, in block "doc"
    {%- block html %}
  File "/home/jevisan/ourPersonalities/venv/lib/python3.6/site-packages/flask_bootstrap/templates/bootstrap/base.html", line 20, in block "html"
    {% block body -%}
  File "/home/jevisan/ourPersonalities/venv/lib/python3.6/site-packages/flask_bootstrap/templates/bootstrap/base.html", line 23, in block "body"
    {% block content -%}
  File "/home/jevisan/ourPersonalities/app/templates/base.html", line 42, in block "content"
    {% block app_content %}{% endblock %}
  File "/home/jevisan/ourPersonalities/app/templates/results_list.html", line 19, in block "app_content"
    <td><a href="{{ url_for('main.analysis_results/'+key) }}">Ver</a></td>
  File "/home/jevisan/ourPersonalities/venv/lib/python3.6/site-packages/flask/helpers.py", line 370, in url_for
    return appctx.app.handle_url_build_error(error, endpoint, values)
  File "/home/jevisan/ourPersonalities/venv/lib/python3.6/site-packages/flask/app.py", line 2215, in handle_url_build_error
    reraise(exc_type, exc_value, tb)
  File "/home/jevisan/ourPersonalities/venv/lib/python3.6/site-packages/flask/_compat.py", line 39, in reraise
    raise value
  File "/home/jevisan/ourPersonalities/venv/lib/python3.6/site-packages/flask/helpers.py", line 358, in url_for
    endpoint, values, method=method, force_external=external
  File "/home/jevisan/ourPersonalities/venv/lib/python3.6/site-packages/werkzeug/routing.py", line 2020, in build
    raise BuildError(endpoint, values, method, self)
werkzeug.routing.BuildError: Could not build url for endpoint 'main.analysis_results/5edfe273-5ba6-4838-bd96-bf291c81657b'. Did you mean 'main.analysis_results' instead?
