2019-08-31 00:40:32,678 : ERROR : Exception on /demo [GET] [in /home/jevisan/UAM/PT/source/ourPersonalities/venv/lib/python3.5/site-packages/flask/app.py:1761]
Traceback (most recent call last):
  File "/home/jevisan/UAM/PT/source/ourPersonalities/venv/lib/python3.5/site-packages/flask/app.py", line 2292, in wsgi_app
    response = self.full_dispatch_request()
  File "/home/jevisan/UAM/PT/source/ourPersonalities/venv/lib/python3.5/site-packages/flask/app.py", line 1815, in full_dispatch_request
    rv = self.handle_user_exception(e)
  File "/home/jevisan/UAM/PT/source/ourPersonalities/venv/lib/python3.5/site-packages/flask/app.py", line 1718, in handle_user_exception
    reraise(exc_type, exc_value, tb)
  File "/home/jevisan/UAM/PT/source/ourPersonalities/venv/lib/python3.5/site-packages/flask/_compat.py", line 35, in reraise
    raise value
  File "/home/jevisan/UAM/PT/source/ourPersonalities/venv/lib/python3.5/site-packages/flask/app.py", line 1813, in full_dispatch_request
    rv = self.dispatch_request()
  File "/home/jevisan/UAM/PT/source/ourPersonalities/venv/lib/python3.5/site-packages/flask/app.py", line 1799, in dispatch_request
    return self.view_functions[rule.endpoint](**req.view_args)
  File "/home/jevisan/ourPersonalities/app/main/routes.py", line 172, in demo
    return render_template('demo.html', title='ourPersonalities Demo', demos=demos)
  File "/home/jevisan/UAM/PT/source/ourPersonalities/venv/lib/python3.5/site-packages/flask/templating.py", line 135, in render_template
    context, ctx.app)
  File "/home/jevisan/UAM/PT/source/ourPersonalities/venv/lib/python3.5/site-packages/flask/templating.py", line 117, in _render
    rv = template.render(context)
  File "/home/jevisan/UAM/PT/source/ourPersonalities/venv/lib/python3.5/site-packages/jinja2/environment.py", line 1008, in render
    return self.environment.handle_exception(exc_info, True)
  File "/home/jevisan/UAM/PT/source/ourPersonalities/venv/lib/python3.5/site-packages/jinja2/environment.py", line 780, in handle_exception
    reraise(exc_type, exc_value, tb)
  File "/home/jevisan/UAM/PT/source/ourPersonalities/venv/lib/python3.5/site-packages/jinja2/_compat.py", line 37, in reraise
    raise value.with_traceback(tb)
  File "/home/jevisan/ourPersonalities/app/templates/demo.html", line 1, in top-level template code
    {% extends "base.html" %}
  File "/home/jevisan/ourPersonalities/app/templates/base.html", line 1, in top-level template code
    {% extends 'bootstrap/base.html' %}
  File "/home/jevisan/UAM/PT/source/ourPersonalities/venv/lib/python3.5/site-packages/flask_bootstrap/templates/bootstrap/base.html", line 1, in top-level template code
    {% block doc -%}
  File "/home/jevisan/UAM/PT/source/ourPersonalities/venv/lib/python3.5/site-packages/flask_bootstrap/templates/bootstrap/base.html", line 4, in block "doc"
    {%- block html %}
  File "/home/jevisan/UAM/PT/source/ourPersonalities/venv/lib/python3.5/site-packages/flask_bootstrap/templates/bootstrap/base.html", line 20, in block "html"
    {% block body -%}
  File "/home/jevisan/UAM/PT/source/ourPersonalities/venv/lib/python3.5/site-packages/flask_bootstrap/templates/bootstrap/base.html", line 26, in block "body"
    {% block scripts %}
  File "/home/jevisan/ourPersonalities/app/templates/demo.html", line 30, in block "scripts"
    window.location = {{ url_for('main.analysis_results') }}+'/'+demo
  File "/home/jevisan/UAM/PT/source/ourPersonalities/venv/lib/python3.5/site-packages/flask/helpers.py", line 356, in url_for
    return appctx.app.handle_url_build_error(error, endpoint, values)
  File "/home/jevisan/UAM/PT/source/ourPersonalities/venv/lib/python3.5/site-packages/flask/app.py", line 2061, in handle_url_build_error
    reraise(exc_type, exc_value, tb)
  File "/home/jevisan/UAM/PT/source/ourPersonalities/venv/lib/python3.5/site-packages/flask/_compat.py", line 35, in reraise
    raise value
  File "/home/jevisan/UAM/PT/source/ourPersonalities/venv/lib/python3.5/site-packages/flask/helpers.py", line 345, in url_for
    force_external=external)
  File "/home/jevisan/UAM/PT/source/ourPersonalities/venv/lib/python3.5/site-packages/werkzeug/routing.py", line 1776, in build
    raise BuildError(endpoint, values, method, self)
werkzeug.routing.BuildError: Could not build url for endpoint 'main.analysis_results'. Did you forget to specify values ['task']?
2019-08-31 00:40:56,735 : INFO : ourPersonalities startup [in /home/jevisan/ourPersonalities/app/__init__.py:74]
2019-08-31 00:42:27,654 : INFO : ourPersonalities startup [in /home/jevisan/ourPersonalities/app/__init__.py:74]
2019-08-31 00:43:36,748 : INFO : ourPersonalities startup [in /home/jevisan/ourPersonalities/app/__init__.py:74]
2019-08-31 00:43:58,073 : INFO : ourPersonalities startup [in /home/jevisan/ourPersonalities/app/__init__.py:74]
2019-08-31 00:48:34,081 : INFO : ourPersonalities startup [in /home/jevisan/ourPersonalities/app/__init__.py:74]
2019-08-31 01:24:10,194 : INFO : ourPersonalities startup [in ./app/__init__.py:74]
2019-08-31 01:24:10,366 : INFO : Solicitando analisis de jevisan85 [in ./app/tasks.py:192]
2019-08-31 01:34:14,723 : INFO : ourPersonalities startup [in ./app/__init__.py:74]
2019-08-31 01:34:14,859 : INFO : Solicitando analisis de GIL_UNAM [in ./app/tasks.py:192]
2019-08-31 13:53:41,818 : INFO : ourPersonalities startup [in /home/jevisan/ourPersonalities/app/__init__.py:74]
2019-08-31 13:54:17,285 : ERROR : Exception on /analyze_user/uamcuajimalpa [GET] [in /home/jevisan/UAM/PT/source/ourPersonalities/venv/lib/python3.5/site-packages/flask/app.py:1761]
Traceback (most recent call last):
  File "/home/jevisan/UAM/PT/source/ourPersonalities/venv/lib/python3.5/site-packages/flask/app.py", line 2292, in wsgi_app
    response = self.full_dispatch_request()
  File "/home/jevisan/UAM/PT/source/ourPersonalities/venv/lib/python3.5/site-packages/flask/app.py", line 1816, in full_dispatch_request
    return self.finalize_request(rv)
  File "/home/jevisan/UAM/PT/source/ourPersonalities/venv/lib/python3.5/site-packages/flask/app.py", line 1831, in finalize_request
    response = self.make_response(rv)
  File "/home/jevisan/UAM/PT/source/ourPersonalities/venv/lib/python3.5/site-packages/flask/app.py", line 1957, in make_response
    'The view function did not return a valid response. The'
TypeError: The view function did not return a valid response. The function either returned None or ended without a return statement.
2019-08-31 14:03:03,244 : INFO : ourPersonalities startup [in ./app/__init__.py:74]
2019-08-31 14:03:03,485 : INFO : Solicitando analisis de uamcuajimalpa [in ./app/tasks.py:194]
2019-08-31 17:11:25,207 : INFO : ourPersonalities startup [in /home/jevisan/ourPersonalities/app/__init__.py:74]
2019-08-31 17:11:48,863 : INFO : ourPersonalities startup [in ./app/__init__.py:74]
2019-08-31 17:11:48,999 : INFO : Solicitando analisis de UNAM_MX [in ./app/tasks.py:193]
2019-08-31 18:11:06,883 : INFO : ourPersonalities startup [in /home/jevisan/ourPersonalities/app/__init__.py:74]
2019-08-31 18:12:12,284 : INFO : ourPersonalities startup [in ./app/__init__.py:74]
2019-08-31 18:12:12,466 : INFO : Solicitando analisis de labteclenguaje [in ./app/tasks.py:192]
2019-08-31 19:27:48,292 : INFO : ourPersonalities startup [in ./app/__init__.py:74]
2019-08-31 19:27:48,447 : INFO : Solicitando analisis de FIUNAM_MX [in ./app/tasks.py:192]
2019-08-31 19:55:28,268 : INFO : ourPersonalities startup [in /home/jevisan/ourPersonalities/app/__init__.py:74]
2019-08-31 20:59:36,928 : INFO : ourPersonalities startup [in ./app/__init__.py:74]
2019-08-31 20:59:37,089 : INFO : Solicitando analisis de LyR_UAMC [in ./app/tasks.py:192]
2019-09-02 10:20:21,124 : INFO : ourPersonalities startup [in /home/jevisan/ourPersonalities/app/__init__.py:74]
2019-09-02 10:22:58,350 : INFO : ourPersonalities startup [in /home/jevisan/ourPersonalities/app/__init__.py:74]
2019-09-02 10:23:56,489 : INFO : ourPersonalities startup [in /home/jevisan/ourPersonalities/app/__init__.py:74]
