2019-09-23 13:21:50,957 : ERROR : Exception on / [GET] [in /home/jevisan/ourPersonalities/venv/lib/python3.6/site-packages/flask/app.py:1891]
Traceback (most recent call last):
  File "/home/jevisan/ourPersonalities/venv/lib/python3.6/site-packages/flask/app.py", line 2446, in wsgi_app
    response = self.full_dispatch_request()
  File "/home/jevisan/ourPersonalities/venv/lib/python3.6/site-packages/flask/app.py", line 1951, in full_dispatch_request
    rv = self.handle_user_exception(e)
  File "/home/jevisan/ourPersonalities/venv/lib/python3.6/site-packages/flask/app.py", line 1820, in handle_user_exception
    reraise(exc_type, exc_value, tb)
  File "/home/jevisan/ourPersonalities/venv/lib/python3.6/site-packages/flask/_compat.py", line 39, in reraise
    raise value
  File "/home/jevisan/ourPersonalities/venv/lib/python3.6/site-packages/flask/app.py", line 1949, in full_dispatch_request
    rv = self.dispatch_request()
  File "/home/jevisan/ourPersonalities/venv/lib/python3.6/site-packages/flask/app.py", line 1935, in dispatch_request
    return self.view_functions[rule.endpoint](**req.view_args)
  File "/home/jevisan/ourPersonalities/app/main/routes.py", line 75, in welcome
    return render_template('welcome.html')
  File "/home/jevisan/ourPersonalities/venv/lib/python3.6/site-packages/flask/templating.py", line 140, in render_template
    ctx.app,
  File "/home/jevisan/ourPersonalities/venv/lib/python3.6/site-packages/flask/templating.py", line 120, in _render
    rv = template.render(context)
  File "/home/jevisan/ourPersonalities/venv/lib/python3.6/site-packages/jinja2/asyncsupport.py", line 76, in render
    return original_render(self, *args, **kwargs)
  File "/home/jevisan/ourPersonalities/venv/lib/python3.6/site-packages/jinja2/environment.py", line 1008, in render
    return self.environment.handle_exception(exc_info, True)
  File "/home/jevisan/ourPersonalities/venv/lib/python3.6/site-packages/jinja2/environment.py", line 780, in handle_exception
    reraise(exc_type, exc_value, tb)
  File "/home/jevisan/ourPersonalities/venv/lib/python3.6/site-packages/jinja2/_compat.py", line 37, in reraise
    raise value.with_traceback(tb)
  File "/home/jevisan/ourPersonalities/app/templates/welcome.html", line 1, in top-level template code
    {% extends 'base.html' %}
  File "/home/jevisan/ourPersonalities/app/templates/base.html", line 1, in top-level template code
    {% extends 'bootstrap/base.html' %}
  File "/home/jevisan/ourPersonalities/venv/lib/python3.6/site-packages/flask_bootstrap/templates/bootstrap/base.html", line 1, in top-level template code
    {% block doc -%}
  File "/home/jevisan/ourPersonalities/venv/lib/python3.6/site-packages/flask_bootstrap/templates/bootstrap/base.html", line 4, in block "doc"
    {%- block html %}
  File "/home/jevisan/ourPersonalities/venv/lib/python3.6/site-packages/flask_bootstrap/templates/bootstrap/base.html", line 20, in block "html"
    {% block body -%}
  File "/home/jevisan/ourPersonalities/venv/lib/python3.6/site-packages/flask_bootstrap/templates/bootstrap/base.html", line 21, in block "body"
    {% block navbar %}
  File "/home/jevisan/ourPersonalities/app/templates/base.html", line 30, in block "navbar"
    <li><a class="" href="{{ url_for('main.acerca') }}">Acerca</a></li>
  File "/home/jevisan/ourPersonalities/venv/lib/python3.6/site-packages/flask/helpers.py", line 370, in url_for
    return appctx.app.handle_url_build_error(error, endpoint, values)
  File "/home/jevisan/ourPersonalities/venv/lib/python3.6/site-packages/flask/app.py", line 2215, in handle_url_build_error
    reraise(exc_type, exc_value, tb)
  File "/home/jevisan/ourPersonalities/venv/lib/python3.6/site-packages/flask/_compat.py", line 39, in reraise
    raise value
  File "/home/jevisan/ourPersonalities/venv/lib/python3.6/site-packages/flask/helpers.py", line 358, in url_for
    endpoint, values, method=method, force_external=external
  File "/home/jevisan/ourPersonalities/venv/lib/python3.6/site-packages/werkzeug/routing.py", line 2020, in build
    raise BuildError(endpoint, values, method, self)
werkzeug.routing.BuildError: Could not build url for endpoint 'main.acerca'. Did you mean 'main.welcome' instead?
2019-09-23 13:22:14,567 : INFO : ourPersonalities startup [in /home/jevisan/ourPersonalities/app/__init__.py:76]
2019-09-23 13:22:31,562 : ERROR : Exception on / [GET] [in /home/jevisan/ourPersonalities/venv/lib/python3.6/site-packages/flask/app.py:1891]
Traceback (most recent call last):
  File "/home/jevisan/ourPersonalities/venv/lib/python3.6/site-packages/flask/app.py", line 2446, in wsgi_app
    response = self.full_dispatch_request()
  File "/home/jevisan/ourPersonalities/venv/lib/python3.6/site-packages/flask/app.py", line 1951, in full_dispatch_request
    rv = self.handle_user_exception(e)
  File "/home/jevisan/ourPersonalities/venv/lib/python3.6/site-packages/flask/app.py", line 1820, in handle_user_exception
    reraise(exc_type, exc_value, tb)
  File "/home/jevisan/ourPersonalities/venv/lib/python3.6/site-packages/flask/_compat.py", line 39, in reraise
    raise value
  File "/home/jevisan/ourPersonalities/venv/lib/python3.6/site-packages/flask/app.py", line 1949, in full_dispatch_request
    rv = self.dispatch_request()
  File "/home/jevisan/ourPersonalities/venv/lib/python3.6/site-packages/flask/app.py", line 1935, in dispatch_request
    return self.view_functions[rule.endpoint](**req.view_args)
  File "/home/jevisan/ourPersonalities/app/main/routes.py", line 75, in welcome
    return render_template('welcome.html')
  File "/home/jevisan/ourPersonalities/venv/lib/python3.6/site-packages/flask/templating.py", line 140, in render_template
    ctx.app,
  File "/home/jevisan/ourPersonalities/venv/lib/python3.6/site-packages/flask/templating.py", line 120, in _render
    rv = template.render(context)
  File "/home/jevisan/ourPersonalities/venv/lib/python3.6/site-packages/jinja2/asyncsupport.py", line 76, in render
    return original_render(self, *args, **kwargs)
  File "/home/jevisan/ourPersonalities/venv/lib/python3.6/site-packages/jinja2/environment.py", line 1008, in render
    return self.environment.handle_exception(exc_info, True)
  File "/home/jevisan/ourPersonalities/venv/lib/python3.6/site-packages/jinja2/environment.py", line 780, in handle_exception
    reraise(exc_type, exc_value, tb)
  File "/home/jevisan/ourPersonalities/venv/lib/python3.6/site-packages/jinja2/_compat.py", line 37, in reraise
    raise value.with_traceback(tb)
  File "/home/jevisan/ourPersonalities/app/templates/welcome.html", line 1, in top-level template code
    {% extends 'base.html' %}
  File "/home/jevisan/ourPersonalities/app/templates/base.html", line 1, in top-level template code
    {% extends 'bootstrap/base.html' %}
  File "/home/jevisan/ourPersonalities/venv/lib/python3.6/site-packages/flask_bootstrap/templates/bootstrap/base.html", line 1, in top-level template code
    {% block doc -%}
  File "/home/jevisan/ourPersonalities/venv/lib/python3.6/site-packages/flask_bootstrap/templates/bootstrap/base.html", line 4, in block "doc"
    {%- block html %}
  File "/home/jevisan/ourPersonalities/venv/lib/python3.6/site-packages/flask_bootstrap/templates/bootstrap/base.html", line 20, in block "html"
    {% block body -%}
  File "/home/jevisan/ourPersonalities/venv/lib/python3.6/site-packages/flask_bootstrap/templates/bootstrap/base.html", line 21, in block "body"
    {% block navbar %}
  File "/home/jevisan/ourPersonalities/app/templates/base.html", line 30, in block "navbar"
    <li><a class="" href="{{ url_for('main.acerca') }}">Acerca</a></li>
  File "/home/jevisan/ourPersonalities/venv/lib/python3.6/site-packages/flask/helpers.py", line 370, in url_for
    return appctx.app.handle_url_build_error(error, endpoint, values)
  File "/home/jevisan/ourPersonalities/venv/lib/python3.6/site-packages/flask/app.py", line 2215, in handle_url_build_error
    reraise(exc_type, exc_value, tb)
  File "/home/jevisan/ourPersonalities/venv/lib/python3.6/site-packages/flask/_compat.py", line 39, in reraise
    raise value
  File "/home/jevisan/ourPersonalities/venv/lib/python3.6/site-packages/flask/helpers.py", line 358, in url_for
    endpoint, values, method=method, force_external=external
  File "/home/jevisan/ourPersonalities/venv/lib/python3.6/site-packages/werkzeug/routing.py", line 2020, in build
    raise BuildError(endpoint, values, method, self)
werkzeug.routing.BuildError: Could not build url for endpoint 'main.acerca'. Did you mean 'main.welcome' instead?
2019-09-23 13:23:05,460 : INFO : ourPersonalities startup [in /home/jevisan/ourPersonalities/app/__init__.py:76]
2019-09-23 13:23:12,822 : ERROR : Exception on /acerca [GET] [in /home/jevisan/ourPersonalities/venv/lib/python3.6/site-packages/flask/app.py:1891]
Traceback (most recent call last):
  File "/home/jevisan/ourPersonalities/venv/lib/python3.6/site-packages/flask/app.py", line 2446, in wsgi_app
    response = self.full_dispatch_request()
  File "/home/jevisan/ourPersonalities/venv/lib/python3.6/site-packages/flask/app.py", line 1951, in full_dispatch_request
    rv = self.handle_user_exception(e)
  File "/home/jevisan/ourPersonalities/venv/lib/python3.6/site-packages/flask/app.py", line 1820, in handle_user_exception
    reraise(exc_type, exc_value, tb)
  File "/home/jevisan/ourPersonalities/venv/lib/python3.6/site-packages/flask/_compat.py", line 39, in reraise
    raise value
  File "/home/jevisan/ourPersonalities/venv/lib/python3.6/site-packages/flask/app.py", line 1949, in full_dispatch_request
    rv = self.dispatch_request()
  File "/home/jevisan/ourPersonalities/venv/lib/python3.6/site-packages/flask/app.py", line 1935, in dispatch_request
    return self.view_functions[rule.endpoint](**req.view_args)
  File "/home/jevisan/ourPersonalities/app/main/routes.py", line 159, in acerca
    print(app.config['FILES_FOLER'])
NameError: name 'app' is not defined
2019-09-23 13:25:25,679 : INFO : ourPersonalities startup [in /home/jevisan/ourPersonalities/app/__init__.py:76]
